Workbook

Sheet Baca_Dulu
A1: Analisis solusi PT Aktu Proteksi: Geo-Solvency Shield
A3: Isi | B3: Buku kerja ini memuat perhitungan matematika keuangan, analisis biaya-manfaat, kepekaan, skenario, dan kerangka bisnis untuk solusi soal 5.
A4: Satuan | B4: Angka model dinyatakan per 100 premi dicatat lini harta benda setahun. Lembar Asumsi mengubahnya ke rupiah lewat skala premi.
A5: Warna | B5: Biru = masukan atau keluaran simulasi yang boleh diganti; hitam = rumus; hijau = rujukan ke lembar lain; kuning = asumsi kunci.
A6: Asal angka model | B6: Lembar Hasil_Model disalin dari G_solusi/keluaran/rancangan.json (simulasi 100.000 tahun; R untuk kerugian bencana, Python untuk neraca).
A7: Solusi terpilih | B7: Batas 10% di zona inti; rasio solvabilitas awal 190%
A8: Tiga jalan | B8: Sekarang = polis standar pada target 120%. Modal saja = polis standar pada target yang lolos tiga kendala. Solusi = rancangan terpilih.
A9: Tiga kendala | B9: C1: P(R < 100%) paling besar 0,5% (kurva campuran). C2: sama, pada kurva Aulady & Fujimi saja. C3: rasio paling rendah 100% setelah skenario megathrust Jawa bagian barat M 8,7 (guncangan median).
A10: Kerangka bisnis | B10: Dipilih menurut aturan satu pertanyaan satu kerangka: 5 Whys (akar masalah), Impact-Effort (prioritas), NPV dan kepekaan (kelayakan finansial), matriks kelayakan empat aspek, Risk Matrix (risiko), Roadmap dan KPI (pelaksanaan).
A11: Lembar | B11: Asumsi, Hasil_Model, Matematika_Keuangan, Biaya_Manfaat, Sensitivitas, Skenario, Lima_Mengapa, Dampak_Upaya, Kelayakan, Risiko, Peta_Jalan_KPI.

Sheet Asumsi
A1: Asumsi dan masukan
A2: Sel biru boleh diganti; lembar lain mengikuti.
A3: Butir | B3: Nilai | C3: Satuan | D3: Status | E3: Sumber atau catatan
A4: Premi harta benda setahun | B4: 1000 | C4: Rp miliar | D4: asumsi | E4: Pada premi Rp1 triliun, ekuitas untuk rasio 120% sekitar Rp228 miliar, dekat dengan ekuitas minimum Rp250 miliar (POJK 23/2023). Premi harta benda terbesar di industri Rp2,2 triliun; median Rp177 miliar (OJK 2024).
A5: Skala: Rp miliar per satuan per 100 premi | B5: =B4/100 -> 10 | C5: Rp miliar | D5: rumus | E5: Pengali dari satuan model ke rupiah
A6: Biaya modal | B6: 0.13 | C6: per tahun | D6: asumsi | E6: Imbal hasil yang dituntut pemegang saham. Patokan: SBN 10 tahun 7,16% ditambah premi risiko ekuitas sekitar 6 poin.
A7: Horizon analisis | B7: 5 | C7: tahun | D7: asumsi | E7: Lembar Biaya_Manfaat disusun untuk lima tahun
A8: Tarif pajak penghasilan badan | B8: 0.22 | D8: regulasi | E8: UU 7/2021
A9: Eksposur gempa per premi harta benda (E) | B9: 139.16 | C9: kali | D9: data | E9: MAIPARK (2025); OJK (2025)
A10: Tarif gempa rata-rata | B10: 1.3498 | C10: per mil | D10: data | E10: MAIPARK (2025)
A11: Porsi premi gempa yang terkena syarat strategi terpilih | B11: 0.67012661 | D11: data | E11: Batas 10% di zona inti; zona inti: Papua, Jawa Barat, Jakarta, Sumatera Utara, Banten; MAIPARK (2025)
A12: Skala premi syarat strategi terpilih (batas10) | B12: 0.6 | D12: regulasi | E12: SEOJK 6/2017 Lampiran III Tabel III.B; dibaca dari strategi terpilih
A13: Komisi | B13: 0.08 | C13: dari premi | D13: data | E13: OJK Tabel 2.10.4
A14: Defisit harapan pemegang polis ikut dihitung (1 = ya, 0 = tidak) | B14: 1 | D14: asumsi | E14: Butsic (1994); Myers & Read (2001)
A16: Biaya pelaksanaan awal (Rp miliar)
A17: Mesin akumulasi dan geokode | B17: 4 | C17: Rp miliar | D17: asumsi | E17: Geokode polis, basis data eksposur, mesin simulasi berbasis data terbuka
A18: Penyesuaian produk dan pelaporan | B18: 1.5 | C18: Rp miliar | D18: asumsi | E18: Klausul first loss, pembaruan pedoman underwriting, pelaporan produk
A19: Pelatihan dan sosialisasi | B19: 0.5 | C19: Rp miliar | D19: asumsi | E19: Underwriter, pemasaran, pialang
A20: Jumlah biaya awal | B20: =SUM(B17:B19) -> 6
A21: Biaya operasi tahunan (Rp miliar)
A22: Tim manajemen eksposur | B22: 1.8 | C22: Rp miliar | D22: asumsi | E22: Tiga orang: aktuaris, analis bahaya, analis data
A23: Data dan komputasi | B23: 0.6 | C23: Rp miliar | D23: asumsi | E23: Pembaruan katalog, data MAIPARK, komputasi
A24: Validasi independen | B24: 0.4 | C24: Rp miliar | D24: asumsi | E24: Telaah model tahunan
A25: Jumlah biaya tahunan | B25: =SUM(B22:B24) -> 2.8
A26: Pengali biaya pelaksanaan (uji) | B26: 1 | E26: Isi 2 untuk menguji biaya dua kali lipat

Sheet Hasil_Model
A1: Keluaran simulasi untuk tiga jalan
A2: Per 100 premi dicatat, kecuali disebut lain. Sel biru = keluaran simulasi 100.000 tahun.
A3: Ukuran | B3: Sekarang | C3: Modal saja | D3: Solusi | E3: Keterangan
A4: Strategi | B4: S0_dasar | C4: S0_dasar | D4: S21_zona_batas10 | E4: Kode strategi pada model bencana
A5: Rasio solvabilitas awal | B5: 1.2 | C5: 3.3 | D5: 1.9 | E5: Tingkat Solvabilitas dibagi MMBR
A6: Ekuitas | B6: 22.897504 | C6: 63.818891 | D6: 36.4162 | E6: Dana pemegang saham yang tertanam
A7: MMBR | B7: 19.081253 | C7: 19.339058 | D7: 19.166421 | E7: SEOJK 24/2017, lima modul
A8: Premi | B8: 100 | C8: 100 | D8: 94.964986 | E8: Setelah premi gempa yang dilepas
A9: Hasil underwriting non-bencana, rata-rata | B9: 30.013652 | C9: 30.013652 | D9: 25.381439
A10: Hasil investasi, rata-rata | B10: 5.906865 | C10: 8.4830512 | D10: 6.757928
A11: Kerugian bencana, rata-rata | B11: 2.5832097 | C11: 2.5832097 | D11: 1.5511809
A12: Kerugian bencana, VaR 99,5% | B12: 53.239602 | C12: 53.239602 | D12: 38.46863 | E12: Kerugian setahun yang terlampaui 1 dari 200 tahun
A13: Kerugian bencana, TVaR 99,5% | B13: 210.31247 | C13: 210.31247 | D13: 89.794418 | E13: Rata-rata kerugian pada 0,5% tahun terburuk
A14: Klaim satu kejadian, VaR 99,5% | B14: 52.117708 | C14: 52.117708 | D14: 37.063906 | E14: Dasar ukuran kantong likuiditas
A15: Laba bersih harapan | B15: 25.802608 | C15: 27.815808 | D15: 23.791474 | E15: Setelah pajak
A16: P(R < 100%), kurva campuran | B16: 0.00709 | C16: 0.00287 | D16: 0.00374 | E16: Kendala C1: paling besar 0,50%
A17: P(R < 100%), kurva Aulady & Fujimi | B17: 0.00837 | C17: 0.00352 | D17: 0.00452 | E17: Kendala C2: paling besar 0,50%
A18: P(R < 0%) | B18: 0.00435 | C18: 0.00226 | D18: 0.00225 | E18: AYD lebih kecil daripada liabilitas
A19: Defisit harapan pemegang polis | B19: 0.76196086 | C19: 0.62718746 | D19: 0.15801762 | E19: Rata-rata kekurangan AYD terhadap liabilitas
A20: Rasio setelah skenario megathrust | B20: -1.2221204 | C20: 1.0433799 | D20: 1.3876301 | E20: Kendala C3: paling rendah 100%
A21: Aset siap cair | B21: 101.0975 | C21: 142.01889 | D21: 114.6162 | E21: Kas, deposito, SBN
A23: Turunan (rumus)
A24: Laba ekonomi = laba bersih - biaya modal x ekuitas | B24: =B15-Asumsi!$B$6*B6 -> 22.825933 | C24: =C15-Asumsi!$B$6*C6 -> 19.519352 | D24: =D15-Asumsi!$B$6*D6 -> 19.057368
A25: Nilai bersih = laba ekonomi - defisit harapan | B25: =B24-Asumsi!$B$14*B19 -> 22.063972 | C25: =C24-Asumsi!$B$14*C19 -> 18.892164 | D25: =D24-Asumsi!$B$14*D19 -> 18.899351
A26: Periode ulang pelanggaran (tahun) | B26: =1/B16 -> 141.04372 | C26: =1/C16 -> 348.43206 | D26: =1/D16 -> 267.37968
A27: Rasio klaim gempa harapan terhadap premi gempa penuh | B27: =B11/(Asumsi!$B$9*Asumsi!$B$10/10) -> 0.13752315 | C27: =C11/(Asumsi!$B$9*Asumsi!$B$10/10) -> 0.13752315 | D27: =D11/(Asumsi!$B$9*Asumsi!$B$10/10) -> 0.082580711
A28: Ekuitas (Rp miliar) | B28: =B6*Asumsi!$B$5 -> 228.97504 | C28: =C6*Asumsi!$B$5 -> 638.18891 | D28: =D6*Asumsi!$B$5 -> 364.162
A29: Laba bersih harapan (Rp miliar) | B29: =B15*Asumsi!$B$5 -> 258.02608 | C29: =C15*Asumsi!$B$5 -> 278.15808 | D29: =D15*Asumsi!$B$5 -> 237.91474
A30: Kerugian 1 dalam 200 tahun (Rp miliar) | B30: =B12*Asumsi!$B$5 -> 532.39602 | C30: =C12*Asumsi!$B$5 -> 532.39602 | D30: =D12*Asumsi!$B$5 -> 384.6863

Sheet Matematika_Keuangan
A1: Matematika keuangan: dari syarat polis ke laba dan likuiditas
A2: Per 100 premi dicatat. Rumus menelusuri angka model langkah demi langkah.
A3: No | B3: Langkah | C3: Nilai | D3: Rumus dalam kata
A4: 1 | B4: Premi gempa pada polis standar | C4: =Asumsi!$B$9*Asumsi!$B$10/10 -> 18.783817 | D4: E x tarif per mil / 1.000 x 100
A5: 2 | B5: Premi gempa yang terkena syarat strategi terpilih | C5: =C4*Asumsi!$B$11 -> 12.587536 | D5: (1) x porsi premi yang terkena syarat
A6: 3 | B6: Premi yang dilepas karena syarat (Batas 10% di zona inti) | C6: =C5*(1-Asumsi!$B$12) -> 5.0350142 | D6: (2) x (1 - skala premi loss limit)
A7: 4 | B7: Komisi yang ikut turun | C7: =C6*Asumsi!$B$13 -> 0.40280114 | D7: (3) x komisi
A8: 5 | B8: Kerugian bencana harapan yang turun | C8: =Hasil_Model!B11-Hasil_Model!D11 -> 1.0320288 | D8: Rata-rata kerugian sekarang - solusi
A9: 6 | B9: Hasil underwriting sebelum pajak yang dilepas | C9: =C6-C7-C8 -> 3.6001843 | D9: (3) - (4) - (5)
A10: 7 | B10: Setelah pajak | C10: =C9*(1-Asumsi!$B$8) -> 2.8081437 | D10: (6) x (1 - tarif pajak)
A11: 8 | B11: Tambahan hasil investasi atas tambahan ekuitas, setelah pajak | C11: =(Hasil_Model!D10-Hasil_Model!B10)*(1-Asumsi!$B$8) -> 0.66382911 | D11: Selisih hasil investasi x (1 - tarif pajak)
A12: 9 | B12: Laba bersih yang dilepas menurut rumus | C12: =C10-C11 -> 2.1443146 | D12: (7) - (8)
A13: 10 | B13: Laba bersih yang dilepas menurut simulasi | C13: =Hasil_Model!B15-Hasil_Model!D15 -> 2.0111339 | D13: Laba bersih sekarang - solusi
A14: 11 | B14: Selisih rumus dan simulasi | C14: =C12-C13 -> 0.13318077 | D14: Timbul karena pajak hanya dikenakan pada tahun laba
A16: Penyangga modal
A17: 12 | B17: Tambahan ekuitas dari 120% ke target solusi | C17: =Hasil_Model!D6-Hasil_Model!B6 -> 13.518696 | D17: Ekuitas solusi - ekuitas sekarang
A18: 13 | B18: Porsi laba bersih setahun yang perlu ditahan | C18: =C17/Hasil_Model!D15 -> 0.56821599 | D18: (12) / laba bersih solusi
A19: 14 | B19: Ekuitas yang dihemat dibanding jalan modal saja | C19: =Hasil_Model!C6-Hasil_Model!D6 -> 27.402691 | D19: Ekuitas modal saja - ekuitas solusi
A20: 15 | B20: Ekuitas solusi sebagai porsi ekuitas modal saja | C20: =Hasil_Model!D6/Hasil_Model!C6 -> 0.57061787
A21: 16 | B21: Tambahan ekuitas (Rp miliar) | C21: =C17*Asumsi!$B$5 -> 135.18696 | D21: x skala
A22: 17 | B22: Ekuitas yang dihemat (Rp miliar) | C22: =C19*Asumsi!$B$5 -> 274.02691 | D22: x skala
A24: Kantong likuiditas bencana: kas dan deposito lawan klaim satu kejadian 1 dalam 200 tahun
B25: Varian profil Konservatif | C25: Kas | D25: Deposito | E25: Kas + deposito | F25: Klaim satu kejadian | G25: Cakupan | H25: Cukup?
B26: SBN 80%, deposito 20% | C26: 7.27 | D26: 21.382889 | E26: =C26+D26 -> 28.652889 | F26: =Hasil_Model!D14 -> 37.063906 | G26: =E26/F26 -> 0.77306717 | H26: =IF(G26>=1,"Ya","Belum") -> Belum
B27: SBN 75%, deposito 25% | C27: 7.27 | D27: 26.782472 | E27: =C27+D27 -> 34.052472 | F27: =Hasil_Model!D14 -> 37.063906 | G27: =E27/F27 -> 0.91875022 | H27: =IF(G27>=1,"Ya","Belum") -> Belum
B28: SBN 70%, deposito 30% | C28: 7.27 | D28: 32.20386 | E28: =C28+D28 -> 39.47386 | F28: =Hasil_Model!D14 -> 37.063906 | G28: =E28/F28 -> 1.0650216 | H28: =IF(G28>=1,"Ya","Belum") -> Ya
B30: Kas dan deposito dicairkan tanpa menjual SBN. Varian yang cakupannya paling sedikit 100% menjadi pilihan alokasi.

Sheet Biaya_Manfaat
A1: Analisis biaya-manfaat
A2: Rp miliar pada skala premi di lembar Asumsi.
A3: A. Solusi lawan jalan modal saja (dua cara mencapai tingkat keamanan yang sama)
A4: Arus kas inkremental | B4: Tahun 0 | C4: Tahun 1 | D4: Tahun 2 | E4: Tahun 3 | F4: Tahun 4 | G4: Tahun 5 | H4: Keterangan
A5: Ekuitas yang tidak perlu disetor | B5: =(Hasil_Model!C6-Hasil_Model!D6)*Asumsi!$B$5 -> 274.02691 | C5: 0 | D5: 0 | E5: 0 | F5: 0 | G5: =-(Hasil_Model!C6-Hasil_Model!D6)*Asumsi!$B$5 -> -274.02691 | H5: Disetor di awal pada jalan modal saja, kembali di akhir horizon
A6: Laba bersih yang dilepas | B6: 0 | C6: =-(Hasil_Model!C15-Hasil_Model!D15)*Asumsi!$B$5 -> -40.243335 | D6: =-(Hasil_Model!C15-Hasil_Model!D15)*Asumsi!$B$5 -> -40.243335 | E6: =-(Hasil_Model!C15-Hasil_Model!D15)*Asumsi!$B$5 -> -40.243335 | F6: =-(Hasil_Model!C15-Hasil_Model!D15)*Asumsi!$B$5 -> -40.243335 | G6: =-(Hasil_Model!C15-Hasil_Model!D15)*Asumsi!$B$5 -> -40.243335 | H6: Premi gempa dilepas dan hasil investasi atas modal yang tidak ditahan
A7: Defisit harapan pemegang polis yang dihindari | B7: 0 | C7: =(Hasil_Model!C19-Hasil_Model!D19)*Asumsi!$B$5*Asumsi!$B$14 -> 4.6916985 | D7: =(Hasil_Model!C19-Hasil_Model!D19)*Asumsi!$B$5*Asumsi!$B$14 -> 4.6916985 | E7: =(Hasil_Model!C19-Hasil_Model!D19)*Asumsi!$B$5*Asumsi!$B$14 -> 4.6916985 | F7: =(Hasil_Model!C19-Hasil_Model!D19)*Asumsi!$B$5*Asumsi!$B$14 -> 4.6916985 | G7: =(Hasil_Model!C19-Hasil_Model!D19)*Asumsi!$B$5*Asumsi!$B$14 -> 4.6916985 | H7: Dihitung bila sakelar di lembar Asumsi bernilai 1
A8: Biaya pelaksanaan awal | B8: =-Asumsi!$B$20*Asumsi!$B$26 -> -6 | C8: 0 | D8: 0 | E8: 0 | F8: 0 | G8: 0 | H8: Mesin akumulasi, penyesuaian produk, pelatihan
A9: Biaya operasi tahunan | B9: 0 | C9: =-Asumsi!$B$25*Asumsi!$B$26 -> -2.8 | D9: =-Asumsi!$B$25*Asumsi!$B$26 -> -2.8 | E9: =-Asumsi!$B$25*Asumsi!$B$26 -> -2.8 | F9: =-Asumsi!$B$25*Asumsi!$B$26 -> -2.8 | G9: =-Asumsi!$B$25*Asumsi!$B$26 -> -2.8 | H9: Tim, data, validasi
A10: Arus kas bersih | B10: =SUM(B5:B9) -> 268.02691 | C10: =SUM(C5:C9) -> -38.351637 | D10: =SUM(D5:D9) -> -38.351637 | E10: =SUM(E5:E9) -> -38.351637 | F10: =SUM(F5:F9) -> -38.351637 | G10: =SUM(G5:G9) -> -312.37855
A11: Faktor diskonto | B11: =1/(1+Asumsi!$B$6)^0 -> 1 | C11: =1/(1+Asumsi!$B$6)^1 -> 0.88495575 | D11: =1/(1+Asumsi!$B$6)^2 -> 0.78314668 | E11: =1/(1+Asumsi!$B$6)^3 -> 0.69305016 | F11: =1/(1+Asumsi!$B$6)^4 -> 0.61331873 | G11: =1/(1+Asumsi!$B$6)^5 -> 0.54275994
A12: Nilai kini | B12: =B10*B11 -> 268.02691 | C12: =C10*C11 -> -33.939501 | D12: =D10*D11 -> -30.034957 | E12: =E10*E11 -> -26.579608 | F12: =F10*F11 -> -23.521777 | G12: =G10*G11 -> -169.54656
A14: Nilai kini bersih (NPV) | B14: =SUM(B12:G12) -> -15.595491 | H14: Positif berarti solusi lebih murah daripada modal saja
A15: Biaya setara modal dari solusi | B15: =IRR(B10:G10,0.1) -> 0.14643246 | H15: Tingkat diskonto yang membuat NPV nol; bandingkan dengan biaya modal
A16: Biaya modal (asumsi) | B16: =Asumsi!$B$6 -> 0.13
A17: Nilai kini manfaat | B17: =B5+NPV(Asumsi!$B$6,C7:G7) -> 290.5287 | H17: Ekuitas tidak disetor dan defisit yang dihindari
A18: Nilai kini biaya | B18: =-(B8+NPV(Asumsi!$B$6,C6:G6)+NPV(Asumsi!$B$6,C9:G9)+G5*G11) -> 306.12419 | H18: Laba dilepas, biaya pelaksanaan, pengembalian ekuitas
A19: Rasio manfaat terhadap biaya | B19: =B17/B18 -> 0.94905502 | H19: Di atas 1 berarti manfaat lebih besar
A20: Keputusan | B20: =IF(B14>0,"Solusi lebih murah daripada modal saja","Modal saja lebih murah; lihat lembar Sensitivitas") -> Modal saja lebih murah; lihat lembar Sensitivitas
A23: B. Solusi lawan keadaan sekarang (yang tidak memenuhi ambang)
A24: Butir | B24: Sekarang | C24: Solusi | D24: Perubahan | H24: Keterangan
A25: Laba ekonomi setahun (Rp miliar) | B25: =Hasil_Model!B24*Asumsi!$B$5 -> 228.25933 | C25: =Hasil_Model!D24*Asumsi!$B$5 -> 190.57368 | D25: =C25-B25 -> -37.685644 | H25: Laba bersih dikurangi biaya modal
A26: Ekuitas (Rp miliar) | B26: =Hasil_Model!B28 -> 228.97504 | C26: =Hasil_Model!D28 -> 364.162 | D26: =C26-B26 -> 135.18696 | H26: Tambahan dapat dibentuk dari laba ditahan
A27: P(R < 100%), kurva campuran | B27: =Hasil_Model!B16 -> 0.00709 | C27: =Hasil_Model!D16 -> 0.00374 | D27: =C27-B27 -> -0.00335 | H27: Ambang 0,50%
A28: P(R < 100%), kurva Aulady & Fujimi | B28: =Hasil_Model!B17 -> 0.00837 | C28: =Hasil_Model!D17 -> 0.00452 | D28: =C28-B28 -> -0.00385 | H28: Ambang 0,50%
A29: Kerugian bencana TVaR 99,5% (Rp miliar) | B29: =Hasil_Model!B13*Asumsi!$B$5 -> 2103.1247 | C29: =Hasil_Model!D13*Asumsi!$B$5 -> 897.94418 | D29: =C29-B29 -> -1205.1805
A30: Defisit harapan pemegang polis (Rp miliar) | B30: =Hasil_Model!B19*Asumsi!$B$5 -> 7.6196086 | C30: =Hasil_Model!D19*Asumsi!$B$5 -> 1.5801762 | D30: =C30-B30 -> -6.0394324
A31: Rasio setelah skenario megathrust | B31: =Hasil_Model!B20 -> -1.2221204 | C31: =Hasil_Model!D20 -> 1.3876301 | D31: =C31-B31 -> 2.6097505 | H31: Paling rendah 100%
A33: Biaya keamanan setahun (Rp miliar) | B33: =-D25+Asumsi!$B$25*Asumsi!$B$26+PMT(Asumsi!$B$6,Asumsi!$B$7,-Asumsi!$B$20*Asumsi!$B$26) -> 42.191531 | H33: Laba ekonomi yang dilepas, biaya operasi, dan anuitas biaya awal
A34: Biaya keamanan terhadap premi | B34: =B33/Asumsi!$B$4 -> 0.042191531
A35: Biaya per 0,1 poin penurunan P(R < 100%) (Rp miliar) | B35: =B33/(-D27*1000) -> 12.594487
A38: C. Pembentukan penyangga dari laba ditahan
A39: Butir (Rp miliar) | B39: Tahun 1 | C39: Tahun 2 | D39: Tahun 3 | E39: Tahun 4 | F39: Tahun 5 | H39: Keterangan
A40: Ekuitas awal tahun | B40: =Hasil_Model!B28 -> 228.97504 | C40: =B44 -> 364.162 | D40: =C44 -> 364.162 | E40: =D44 -> 364.162 | F40: =E44 -> 364.162
A41: Laba bersih harapan | B41: =Hasil_Model!D29 -> 237.91474 | C41: =Hasil_Model!D29 -> 237.91474 | D41: =Hasil_Model!D29 -> 237.91474 | E41: =Hasil_Model!D29 -> 237.91474 | F41: =Hasil_Model!D29 -> 237.91474
A42: Laba ditahan untuk penyangga | B42: =MAX(0,MIN(B41,B45-B40)) -> 135.18696 | C42: =MAX(0,MIN(C41,C45-C40)) -> 0 | D42: =MAX(0,MIN(D41,D45-D40)) -> 0 | E42: =MAX(0,MIN(E41,E45-E40)) -> 0 | F42: =MAX(0,MIN(F41,F45-F40)) -> 0 | H42: Penyangga dibentuk dulu, baru laba dibagikan
A43: Laba yang dapat dibagikan | B43: =B41-B42 -> 102.72778 | C43: =C41-C42 -> 237.91474 | D43: =D41-D42 -> 237.91474 | E43: =E41-E42 -> 237.91474 | F43: =F41-F42 -> 237.91474
A44: Ekuitas akhir tahun | B44: =B40+B42 -> 364.162 | C44: =C40+C42 -> 364.162 | D44: =D40+D42 -> 364.162 | E44: =E40+E42 -> 364.162 | F44: =F40+F42 -> 364.162
A45: Ekuitas sasaran | B45: =Hasil_Model!D28 -> 364.162 | C45: =Hasil_Model!D28 -> 364.162 | D45: =Hasil_Model!D28 -> 364.162 | E45: =Hasil_Model!D28 -> 364.162 | F45: =Hasil_Model!D28 -> 364.162
A48: D. Perspektif perusahaan, uji biaya dua kali, dan kerugian yang dialihkan (Rev. 2)
...

Sheet Sensitivitas
A1: Kepekaan nilai kini bersih (solusi lawan modal saja)
A2: Rp miliar. Rumus tertutup: NPV = dE x (1 - v^n) - (dLaba - dDefisit + biaya tahunan) x a(n,k) - biaya awal.
A3: Masukan dasar (dari lembar lain)
A4: Ekuitas dihemat (dE) | B4: =(Hasil_Model!C6-Hasil_Model!D6)*Asumsi!$B$5 -> 274.02691
A5: Laba bersih dilepas setahun (dLaba) | B5: =(Hasil_Model!C15-Hasil_Model!D15)*Asumsi!$B$5 -> 40.243335
A6: Defisit dihindari setahun (dDefisit) | B6: =(Hasil_Model!C19-Hasil_Model!D19)*Asumsi!$B$5*Asumsi!$B$14 -> 4.6916985
A7: Biaya operasi tahunan | B7: =Asumsi!$B$25*Asumsi!$B$26 -> 2.8
A8: Biaya awal | B8: =Asumsi!$B$20*Asumsi!$B$26 -> 6
A10: 1. Biaya modal
A11: Biaya modal | B11: NPV | C11: Keputusan
A12: 0.1 | B12: =$B$4*(1-(1+A12)^-Asumsi!$B$7)-($B$5-$B$6+$B$7)*(1-(1+A12)^-Asumsi!$B$7)/A12-$B$8 -> -47.505116 | C12: =IF(B12>0,"Solusi lebih murah","Modal saja lebih murah") -> Modal saja lebih murah
A13: 0.11 | B13: =$B$4*(1-(1+A13)^-Asumsi!$B$7)-($B$5-$B$6+$B$7)*(1-(1+A13)^-Asumsi!$B$7)/A13-$B$8 -> -36.338421 | C13: =IF(B13>0,"Solusi lebih murah","Modal saja lebih murah") -> Modal saja lebih murah
A14: 0.12 | B14: =$B$4*(1-(1+A14)^-Asumsi!$B$7)-($B$5-$B$6+$B$7)*(1-(1+A14)^-Asumsi!$B$7)/A14-$B$8 -> -25.712383 | C14: =IF(B14>0,"Solusi lebih murah","Modal saja lebih murah") -> Modal saja lebih murah
A15: 0.13 | B15: =$B$4*(1-(1+A15)^-Asumsi!$B$7)-($B$5-$B$6+$B$7)*(1-(1+A15)^-Asumsi!$B$7)/A15-$B$8 -> -15.595491 | C15: =IF(B15>0,"Solusi lebih murah","Modal saja lebih murah") -> Modal saja lebih murah
A16: 0.14 | B16: =$B$4*(1-(1+A16)^-Asumsi!$B$7)-($B$5-$B$6+$B$7)*(1-(1+A16)^-Asumsi!$B$7)/A16-$B$8 -> -5.9583517 | C16: =IF(B16>0,"Solusi lebih murah","Modal saja lebih murah") -> Modal saja lebih murah
A17: 0.15 | B17: =$B$4*(1-(1+A17)^-Asumsi!$B$7)-($B$5-$B$6+$B$7)*(1-(1+A17)^-Asumsi!$B$7)/A17-$B$8 -> 3.2264737 | C17: =IF(B17>0,"Solusi lebih murah","Modal saja lebih murah") -> Solusi lebih murah
A18: 0.16 | B18: =$B$4*(1-(1+A18)^-Asumsi!$B$7)-($B$5-$B$6+$B$7)*(1-(1+A18)^-Asumsi!$B$7)/A18-$B$8 -> 11.984614 | C18: =IF(B18>0,"Solusi lebih murah","Modal saja lebih murah") -> Solusi lebih murah
A20: 2. Horizon
A21: Horizon (tahun) | B21: NPV | C21: Keputusan
A22: 3 | B22: =$B$4*(1-(1+Asumsi!$B$6)^-A22)-($B$5-$B$6+$B$7)*(1-(1+Asumsi!$B$6)^-A22)/Asumsi!$B$6-$B$8 -> -12.441549 | C22: =IF(B22>0,"Solusi lebih murah","Modal saja lebih murah") -> Modal saja lebih murah
A23: 5 | B23: =$B$4*(1-(1+Asumsi!$B$6)^-A23)-($B$5-$B$6+$B$7)*(1-(1+Asumsi!$B$6)^-A23)/Asumsi!$B$6-$B$8 -> -15.595491 | C23: =IF(B23>0,"Solusi lebih murah","Modal saja lebih murah") -> Modal saja lebih murah
A24: 7 | B24: =$B$4*(1-(1+Asumsi!$B$6)^-A24)-($B$5-$B$6+$B$7)*(1-(1+Asumsi!$B$6)^-A24)/Asumsi!$B$6-$B$8 -> -18.06549 | C24: =IF(B24>0,"Solusi lebih murah","Modal saja lebih murah") -> Modal saja lebih murah
A25: 10 | B25: =$B$4*(1-(1+Asumsi!$B$6)^-A25)-($B$5-$B$6+$B$7)*(1-(1+Asumsi!$B$6)^-A25)/Asumsi!$B$6-$B$8 -> -20.803539 | C25: =IF(B25>0,"Solusi lebih murah","Modal saja lebih murah") -> Modal saja lebih murah
A27: 3. Asumsi model (target tiap jalan dihitung ulang oleh simulasi)
A28: Kasus | B28: Target modal saja | C28: Target solusi | D28: Ekuitas modal saja | E28: Ekuitas solusi | F28: Laba modal saja | G28: Laba solusi | H28: Defisit modal saja | I28: Defisit solusi | J28: NPV (Rp miliar) | K28: Ekuitas solusi / modal saja
A29: Dasar | B29: 3.3 | C29: 1.9 | D29: 63.818891 | E29: 36.4162 | F29: 27.815808 | G29: 23.791474 | H29: 0.62718746 | I29: 0.15801762 | J29: =((D29-E29)*Asumsi!$B$5)*(1-(1+Asumsi!$B$6)^-Asumsi!$B$7)-(((F29-G29)*Asumsi!$B$5)-((H29-I29)*Asumsi!$B$5*Asumsi!$B$14)+$B$7)*(1-(1+Asumsi!$B$6)^-Asumsi!$B$7)/Asumsi!$B$6-$B$8 -> -15.595491 | K29: =E29/D29 -> 0.57061787
A30: Eksposur per premi 122 | B30: 2.8 | C30: 1.6 | D30: 53.975729 | E30: 30.607724 | F30: 27.61135 | G30: 24.114442 | H30: 0.5451461 | I30: 0.13243073 | J30: =((D30-E30)*Asumsi!$B$5)*(1-(1+Asumsi!$B$6)^-Asumsi!$B$7)-(((F30-G30)*Asumsi!$B$5)-((H30-I30)*Asumsi!$B$5*Asumsi!$B$14)+$B$7)*(1-(1+Asumsi!$B$6)^-Asumsi!$B$7)/Asumsi!$B$6-$B$8 -> -17.478542 | K30: =E30/D30 -> 0.56706458
A31: Eksposur per premi 188 | B31: 4.65 | C31: 2.75 | D31: 90.714527 | E31: 52.994884 | F31: 28.344851 | G31: 22.884116 | H31: 0.86166254 | I31: 0.23164407 | J31: =((D31-E31)*Asumsi!$B$5)*(1-(1+Asumsi!$B$6)^-Asumsi!$B$7)-(((F31-G31)*Asumsi!$B$5)-((H31-I31)*Asumsi!$B$5*Asumsi!$B$14)+$B$7)*(1-(1+Asumsi!$B$6)^-Asumsi!$B$7)/Asumsi!$B$6-$B$8 -> -13.286378 | K31: =E31/D31 -> 0.58419401
A32: Biaya akuisisi 15% premi | B32: 3.6 | C32: 2.25 | D32: 69.755245 | E32: 43.220904 | F32: 22.634739 | G32: 18.929919 | H32: 0.62882375 | I32: 0.15678012 | J32: =((D32-E32)*Asumsi!$B$5)*(1-(1+Asumsi!$B$6)^-Asumsi!$B$7)-(((F32-G32)*Asumsi!$B$5)-((H32-I32)*Asumsi!$B$5*Asumsi!$B$14)+$B$7)*(1-(1+Asumsi!$B$6)^-Asumsi!$B$7)/Asumsi!$B$6-$B$8 -> -8.2268164 | K32: =E32/D32 -> 0.61960794
A33: Rasio klaim non-bencana 29,5% | B33: 2.55 | C33: 1.2 | D33: 49.077782 | E33: 22.897504 | F33: 39.208162 | G33: 35.240023 | H33: 0.62726956 | I33: 0.15527568 | J33: =((D33-E33)*Asumsi!$B$5)*(1-(1+Asumsi!$B$6)^-Asumsi!$B$7)-(((F33-G33)*Asumsi!$B$5)-((H33-I33)*Asumsi!$B$5*Asumsi!$B$14)+$B$7)*(1-(1+Asumsi!$B$6)^-Asumsi!$B$7)/Asumsi!$B$6-$B$8 -> -19.109036 | K33: =E33/D33 -> 0.46655539
A35: Titik impas biaya modal (NPV = 0) pada kasus dasar | B35: =Biaya_Manfaat!B15 -> 0.14643246
A36: Di atas titik ini solusi lebih murah daripada menambah modal; di bawahnya modal lebih murah.

Sheet Skenario
A1: Uji skenario gempa (Scenario Analysis)
A2: Kerugian satu kejadian pada kurva campuran; underwriting dan investasi pada nilai harapan.
A3: Skenario | B3: Guncangan | C3: Jalan | D3: Rasio awal | E3: Kerugian (per 100 premi) | F3: Kerugian (Rp miliar) | G3: Rasio akhir | H3: Kekurangan kas (per 100 premi) | I3: Status
A4: Gempa dangkal dekat Timika M 7,5 | B4: median | C4: Sekarang | D4: 1.2 | E4: 10.852239 | F4: =E4*Asumsi!$B$5 -> 108.52239 | G4: 2.2242601 | H4: 0 | I4: =IF(G4>=1.2,"Di atas target minimum",IF(G4>=1,"Memenuhi 100%",IF(G4>=0,"Di bawah 100%","AYD di bawah liabilitas"))) -> Di atas target minimum
A5: Gempa dangkal dekat Timika M 7,5 | B5: median | C5: Solusi | D5: 1.9 | E5: 5.5972916 | F5: =E5*Asumsi!$B$5 -> 55.972916 | G5: 2.9804192 | H5: 0 | I5: =IF(G5>=1.2,"Di atas target minimum",IF(G5>=1,"Memenuhi 100%",IF(G5>=0,"Di bawah 100%","AYD di bawah liabilitas"))) -> Di atas target minimum
A6: Gempa dangkal dekat Timika M 7,5 | B6: median + 1 simpangan baku | C6: Sekarang | D6: 1.2 | E6: 45.550002 | F6: =E6*Asumsi!$B$5 -> 455.50002 | G6: 0.68559464 | H6: 0 | I6: =IF(G6>=1.2,"Di atas target minimum",IF(G6>=1,"Memenuhi 100%",IF(G6>=0,"Di bawah 100%","AYD di bawah liabilitas"))) -> Di bawah 100%
A7: Gempa dangkal dekat Timika M 7,5 | B7: median + 1 simpangan baku | C7: Solusi | D7: 1.9 | E7: 22.349154 | F7: =E7*Asumsi!$B$5 -> 223.49154 | G7: 2.2955988 | H7: 0 | I7: =IF(G7>=1.2,"Di atas target minimum",IF(G7>=1,"Memenuhi 100%",IF(G7>=0,"Di bawah 100%","AYD di bawah liabilitas"))) -> Di atas target minimum
A8: Megathrust Jawa bagian barat M 8,7 | B8: median | C8: Sekarang | D8: 1.2 | E8: 81.769588 | F8: =E8*Asumsi!$B$5 -> 817.69588 | G8: -1.2221204 | H8: 0 | I8: =IF(G8>=1.2,"Di atas target minimum",IF(G8>=1,"Memenuhi 100%",IF(G8>=0,"Di bawah 100%","AYD di bawah liabilitas"))) -> AYD di bawah liabilitas
A9: Megathrust Jawa bagian barat M 8,7 | B9: median | C9: Solusi | D9: 1.9 | E9: 41.792532 | F9: =E9*Asumsi!$B$5 -> 417.92532 | G9: 1.3876301 | H9: 0 | I9: =IF(G9>=1.2,"Di atas target minimum",IF(G9>=1,"Memenuhi 100%",IF(G9>=0,"Di bawah 100%","AYD di bawah liabilitas"))) -> Di atas target minimum
A10: Megathrust Jawa bagian barat M 8,7 | B10: median + 1 simpangan baku | C10: Sekarang | D10: 1.2 | E10: 340.16625 | F10: =E10*Asumsi!$B$5 -> 3401.6625 | G10: -14.769 | H10: 239.53789 | I10: =IF(G10>=1.2,"Di atas target minimum",IF(G10>=1,"Memenuhi 100%",IF(G10>=0,"Di bawah 100%","AYD di bawah liabilitas"))) -> AYD di bawah liabilitas
A11: Megathrust Jawa bagian barat M 8,7 | B11: median + 1 simpangan baku | C11: Solusi | D11: 1.9 | E11: 156.20228 | F11: =E11*Asumsi!$B$5 -> 1562.0228 | G11: -4.6006033 | H11: 42.122814 | I11: =IF(G11>=1.2,"Di atas target minimum",IF(G11>=1,"Memenuhi 100%",IF(G11>=0,"Di bawah 100%","AYD di bawah liabilitas"))) -> AYD di bawah liabilitas
A12: Megathrust Mentawai M 8,9 | B12: median | C12: Sekarang | D12: 1.2 | E12: 8.8684024 | F12: =E12*Asumsi!$B$5 -> 88.684024 | G12: 2.3057626 | H12: 0 | I12: =IF(G12>=1.2,"Di atas target minimum",IF(G12>=1,"Memenuhi 100%",IF(G12>=0,"Di bawah 100%","AYD di bawah liabilitas"))) -> Di atas target minimum
A13: Megathrust Mentawai M 8,9 | B13: median | C13: Solusi | D13: 1.9 | E13: 8.8211557 | F13: =E13*Asumsi!$B$5 -> 88.211557 | G13: 2.8489031 | H13: 0 | I13: =IF(G13>=1.2,"Di atas target minimum",IF(G13>=1,"Memenuhi 100%",IF(G13>=0,"Di bawah 100%","AYD di bawah liabilitas"))) -> Di atas target minimum
A14: Megathrust Mentawai M 8,9 | B14: median + 1 simpangan baku | C14: Sekarang | D14: 1.2 | E14: 43.857322 | F14: =E14*Asumsi!$B$5 -> 438.57322 | G14: 0.77474946 | H14: 0 | I14: =IF(G14>=1.2,"Di atas target minimum",IF(G14>=1,"Memenuhi 100%",IF(G14>=0,"Di bawah 100%","AYD di bawah liabilitas"))) -> Di bawah 100%
A15: Megathrust Mentawai M 8,9 | B15: median + 1 simpangan baku | C15: Solusi | D15: 1.9 | E15: 42.979091 | F15: =E15*Asumsi!$B$5 -> 429.79091 | G15: 1.3254108 | H15: 0 | I15: =IF(G15>=1.2,"Di atas target minimum",IF(G15>=1,"Memenuhi 100%",IF(G15>=0,"Di bawah 100%","AYD di bawah liabilitas"))) -> Di atas target minimum
... A23: Sesar Surabaya M 6,5 | B23: median + 1 simpangan baku | C23: Solusi | D23: 1.9 | E23: 118.80048 | F23: =E23*Asumsi!$B$5 -> 1188.0048 | G23: -2.6491799 | H23: 4.7210116 | I23: =IF(G23>=1.2,"Di atas target minimum",IF(G23>=1,"Memenuhi 100%",IF(G23>=0,"Di bawah 100%","AYD di bawah liabilitas"))) -> AYD di bawah liabilitas

Sheet Lima_Mengapa
A1: Akar masalah: 5 Whys
A2: Dipilih karena ada satu rantai sebab yang dominan. Angka dari Hasil_Model dan simulasi.
A4: Masalah | B4: Pada target 120% peluang rasio solvabilitas jatuh di bawah 100% dalam setahun 0,71%, di atas ambang 0,5%.
A5: Mengapa 1 | B5: Kerugian bencana 1 dalam 200 tahun 53 per 100 premi, sedangkan penyangga 20% di atas MMBR hanya 3,8 dan laba bersih setahun 26.
A6: Mengapa 2 | B6: Seluruh eksposur gempa ditahan sendiri dan polis standar mengganti sampai nilai pertanggungan penuh; yang dipotong hanya risiko sendiri 2,5%.
A7: Mengapa 3 | B7: Eksposur terkumpul. Lima provinsi memuat 62% eksposur dan sekitar 85% kerugian tahun ekor; 3,3% risiko memuat 82% eksposur.
A8: Mengapa 4 | B8: MMBR menghitung risiko asuransi dari cadangan (25% CAPYBMP, 20% cadangan klaim), bukan dari eksposur bencana. Modul asuransi 16,3 per 100 premi.
A9: Mengapa 5 | B9: Belum ada batas kerugian kontraktual di zona yang menumpuk, dan besar eksposur yang boleh ditahan belum dikaitkan dengan modal.
A10: Akar masalah | B10: Eksposur gempa yang terkumpul dan tidak berbatas belum terhubung dengan ukuran modal.
A11: Lalu apa | B11: Solusi harus membatasi kerugian per risiko di zona inti dan menetapkan target modal dari uji peluang serta uji skenario, bukan dari angka minimum regulasi.

Sheet Dampak_Upaya
A1: Prioritas strategi mitigasi: Impact-Effort Matrix
A2: Dampak = penurunan P(R < 100%) pada target 120%; upaya = laba bersih yang dilepas. Keduanya keluaran simulasi.
A3: Strategi | B3: Keterangan | C3: Upaya: laba dilepas (per 100 premi) | D3: P(R < 100%) | E3: Dampak: penurunan peluang (poin persen) | F3: Kuadran
A4: S1_rs5 | B4: Risiko sendiri 5% | C4: -0.29165865 | D4: 0.00621 | E4: =(0.00709-D4)*100 -> 0.088 | F4: =IF(E4>=$C$31,IF(C4<=$C$30,"Kerjakan dulu","Proyek besar"),IF(C4<=$C$30,"Tambahan cepat","Hindari")) -> Tambahan cepat
A5: S2_rs10 | B5: Risiko sendiri 10% | C5: -0.71589328 | D5: 0.00463 | E5: =(0.00709-D5)*100 -> 0.246 | F5: =IF(E5>=$C$31,IF(C5<=$C$30,"Kerjakan dulu","Proyek besar"),IF(C5<=$C$30,"Tambahan cepat","Hindari")) -> Kerjakan dulu
A6: S3_batas20 | B6: Batas ganti rugi gempa 20% nilai pertanggungan per risiko | C6: 3.1551724 | D6: 0.00464 | E6: =(0.00709-D6)*100 -> 0.245 | F6: =IF(E6>=$C$31,IF(C6<=$C$30,"Kerjakan dulu","Proyek besar"),IF(C6<=$C$30,"Tambahan cepat","Hindari")) -> Proyek besar
A7: S4_batas10 | B7: Batas ganti rugi gempa 10% nilai pertanggungan per risiko | C7: 4.0256687 | D7: 0.00289 | E7: =(0.00709-D7)*100 -> 0.42 | F7: =IF(E7>=$C$31,IF(C7<=$C$30,"Kerjakan dulu","Proyek besar"),IF(C7<=$C$30,"Tambahan cepat","Hindari")) -> Proyek besar
A8: S5_akumulasi10 | B8: Batas akumulasi 10% per provinsi | C8: 2.2697251 | D8: 0.00657 | E8: =(0.00709-D8)*100 -> 0.052 | F8: =IF(E8>=$C$31,IF(C8<=$C$30,"Kerjakan dulu","Proyek besar"),IF(C8<=$C$30,"Tambahan cepat","Hindari")) -> Tambahan cepat
A9: S6_koas50 | B9: Koasuransi 50% di Jakarta, Jawa Barat, Banten | C9: 2.6925119 | D9: 0.00667 | E9: =(0.00709-D9)*100 -> 0.042 | F9: =IF(E9>=$C$31,IF(C9<=$C$30,"Kerjakan dulu","Proyek besar"),IF(C9<=$C$30,"Tambahan cepat","Hindari")) -> Tambahan cepat
A10: S7_paketA | B10: Paket A: risiko sendiri 5%, batas 20%, akumulasi 10% | C10: 4.6257322 | D10: 0.00329 | E10: =(0.00709-D10)*100 -> 0.38 | F10: =IF(E10>=$C$31,IF(C10<=$C$30,"Kerjakan dulu","Proyek besar"),IF(C10<=$C$30,"Tambahan cepat","Hindari")) -> Proyek besar
A11: S8_paketB | B11: Paket B: paket A dan koasuransi 50% | C11: 5.8823027 | D11: 0.00318 | E11: =(0.00709-D11)*100 -> 0.391 | F11: =IF(E11>=$C$31,IF(C11<=$C$30,"Kerjakan dulu","Proyek besar"),IF(C11<=$C$30,"Tambahan cepat","Hindari")) -> Proyek besar
A12: S9_batas50 | B12: Batas ganti rugi gempa 50% | C12: 1.7807385 | D12: 0.00703 | E12: =(0.00709-D12)*100 -> 0.006 | F12: =IF(E12>=$C$31,IF(C12<=$C$30,"Kerjakan dulu","Proyek besar"),IF(C12<=$C$30,"Tambahan cepat","Hindari")) -> Tambahan cepat
A13: S10_batas40 | B13: Batas ganti rugi gempa 40% | C13: 2.0192219 | D13: 0.00648 | E13: =(0.00709-D13)*100 -> 0.061 | F13: =IF(E13>=$C$31,IF(C13<=$C$30,"Kerjakan dulu","Proyek besar"),IF(C13<=$C$30,"Tambahan cepat","Hindari")) -> Tambahan cepat
A14: S11_batas30 | B14: Batas ganti rugi gempa 30% | C14: 2.3652871 | D14: 0.00554 | E14: =(0.00709-D14)*100 -> 0.155 | F14: =IF(E14>=$C$31,IF(C14<=$C$30,"Kerjakan dulu","Proyek besar"),IF(C14<=$C$30,"Tambahan cepat","Hindari")) -> Tambahan cepat
A15: S12_batas25 | B15: Batas ganti rugi gempa 25% | C15: 2.6492607 | D15: 0.0051 | E15: =(0.00709-D15)*100 -> 0.199 | F15: =IF(E15>=$C$31,IF(C15<=$C$30,"Kerjakan dulu","Proyek besar"),IF(C15<=$C$30,"Tambahan cepat","Hindari")) -> Kerjakan dulu
... A28: S25_zona_batas15 | B28: Batas 15% di zona inti | C28: 2.4078065 | D28: 0.0064 | E28: =(0.00709-D28)*100 -> 0.069 | F28: =IF(E28>=$C$31,IF(C28<=$C$30,"Kerjakan dulu","Proyek besar"),IF(C28<=$C$30,"Tambahan cepat","Hindari")) -> Tambahan cepat
A30: Batas upaya (median) | C30: =MEDIAN(C4:C28) -> 2.6925119
A31: Batas dampak (median) | C31: =MEDIAN(E4:E28) -> 0.199
A33: Batasan: risiko sendiri di atas 2,5% tampak tanpa biaya karena tabel tarif tidak memberi potongan premi; strategi itu tidak dijadikan calon.

Sheet Kelayakan
A1: Analisis kelayakan empat aspek
A2: Skor 1 (lemah) sampai 5 (kuat) adalah penilaian penulis atas bukti di kolom D; bobot dapat diganti.
A3: Aspek | B3: Kriteria | C3: Lensa | D3: Bukti | E3: Skor | F3: Bobot | G3: Skor x bobot | H3: Syarat agar tetap layak
A4: Operasional | B4: Perubahan produk terbatas | C4: feasible | D4: Hanya dasar nilai pertanggungan jaminan gempa di lima provinsi yang berubah; jaminan kebakaran tetap nilai penuh. | E4: 4 | F4: 0.08 | G4: =E4*F4 -> 0.32 | H4: Berlaku saat polis baru dan perpanjangan
A5: Operasional | B5: Data lokasi polis tersedia | C5: feasible | D5: Zona tarif gempa sudah ditetapkan per kabupaten/kota, jadi alamat risiko sudah dicatat. | E5: 4 | F5: 0.06 | G5: =E5*F5 -> 0.24 | H5: Koordinat wajib untuk nilai pertanggungan di atas Rp50 miliar
A6: Operasional | B6: Penerimaan nasabah dan pialang | C6: desirable | D6: Premi gempa turun 40% menurut skala loss limit; kreditur dapat menuntut nilai penuh. | E6: 3 | F6: 0.1 | G6: =E6*F6 -> 0.3 | H6: Lapisan di atas batas ditawarkan lewat koasuransi dengan penanggung lain
A7: Operasional | B7: Sumber daya manusia | C7: feasible | D7: Tim tiga orang (aktuaris, analis bahaya, analis data). | E7: 4 | F7: 0.04 | G7: =E7*F7 -> 0.16 | H7: Pelatihan underwriter dan pemasaran
A8: Hukum dan regulasi | B8: Dasar nilai pertanggungan first loss | C8: feasible | D8: SEOJK 6/2017 Bagian VI angka 1 huruf a membolehkan first loss/sub limit basis untuk asuransi gempa. | E8: 5 | F8: 0.1 | G8: =E8*F8 -> 0.5 | H8: Nilai deklarasi sama dengan nilai sebenarnya
A9: Hukum dan regulasi | B9: Tarif premi | C9: feasible | D9: Skala premi polis loss limit ada di SEOJK 6/2017 Lampiran III Tabel III.B. | E9: 5 | F9: 0.06 | G9: =E9*F9 -> 0.3 | H9: Tarif zona tetap dipakai
A10: Hukum dan regulasi | B10: Target solvabilitas internal | C10: feasible | D10: POJK 26/2025 Pasal 3 meminta target paling rendah 120% dengan memperhitungkan profil risiko dan hasil stress test. | E10: 5 | F10: 0.08 | G10: =E10*F10 -> 0.4 | H10: Target dan dasarnya disetujui direksi dan dewan komisaris
A11: Hukum dan regulasi | B11: Batas investasi | C11: feasible | D11: Profil Konservatif memenuhi seluruh batas AYD Pasal 15 POJK 26/2025. | E11: 5 | F11: 0.06 | G11: =E11*F11 -> 0.3 | H11: Deposito paling banyak 20% per bank
A12: Teknologi | B12: Mesin simulasi | C12: feasible | D12: Model berbasis kejadian dan simulasi neraca sudah berjalan: 100.000 tahun dalam hitungan menit di komputer biasa, dengan R dan Python. | E12: 4 | F12: 0.08 | G12: =E12*F12 -> 0.32 | H12: Kode dan data diarsipkan; uji otomatis dijalankan tiap pembaruan
A13: Teknologi | B13: Data | C13: feasible | D13: Katalog USGS, statistik MAIPARK, dan statistik OJK terbuka dan diperbarui berkala. | E13: 4 | F13: 0.05 | G13: =E13*F13 -> 0.2 | H13: Data polis sendiri menggantikan sebaran industri
A14: Teknologi | B14: Ketepatan model | C14: feasible | D14: Uji balik menunjukkan model di bawah klaim nyata untuk gempa dekat sumber; kurva kerentanan memberi rentang lebar. | E14: 2 | F14: 0.07 | G14: =E14*F14 -> 0.14 | H14: Kalibrasi tahunan dan validasi independen; target memuat kurva terberat
A15: Modal | B15: Tambahan ekuitas | C15: viable | D15: Tambahan 13,5 per 100 premi, 57% laba bersih setahun. | E15: 5 | F15: 0.1 | G15: =E15*F15 -> 0.5 | H15: Laba ditahan sampai penyangga terbentuk
... A17: Modal | B17: Nilai ekonomi | C17: viable | D17: Nilai kini bersih terhadap jalan modal saja bergantung pada biaya modal; lihat lembar Sensitivitas. | E17: 3 | F17: 0.05 | G17: =E17*F17 -> 0.15 | H17: Biaya modal di atas titik impas
A19: Ringkasan per aspek
A20: Aspek | B20: Jumlah bobot | C20: Skor rata-rata tertimbang | D20: Putusan
A21: Operasional | B21: =SUMIF($A$4:$A$17,A21,$F$4:$F$17) -> 0.28 | C21: =SUMIF($A$4:$A$17,A21,$G$4:$G$17)/B21 -> 3.6428571 | D21: =IF(C21>=4,"Layak",IF(C21>=3,"Layak bersyarat","Belum layak")) -> Layak bersyarat
A22: Hukum dan regulasi | B22: =SUMIF($A$4:$A$17,A22,$F$4:$F$17) -> 0.3 | C22: =SUMIF($A$4:$A$17,A22,$G$4:$G$17)/B22 -> 5 | D22: =IF(C22>=4,"Layak",IF(C22>=3,"Layak bersyarat","Belum layak")) -> Layak
A23: Teknologi | B23: =SUMIF($A$4:$A$17,A23,$F$4:$F$17) -> 0.2 | C23: =SUMIF($A$4:$A$17,A23,$G$4:$G$17)/B23 -> 3.3 | D23: =IF(C23>=4,"Layak",IF(C23>=3,"Layak bersyarat","Belum layak")) -> Layak bersyarat
A24: Modal | B24: =SUMIF($A$4:$A$17,A24,$F$4:$F$17) -> 0.22 | C24: =SUMIF($A$4:$A$17,A24,$G$4:$G$17)/B24 -> 4.5454545 | D24: =IF(C24>=4,"Layak",IF(C24>=3,"Layak bersyarat","Belum layak")) -> Layak
A25: Seluruh aspek | B25: =SUM(F4:F17) -> 1 | C25: =SUM(G4:G17)/B25 -> 4.18 | D25: =IF(C25>=4,"Layak",IF(C25>=3,"Layak bersyarat","Belum layak")) -> Layak

Sheet Risiko
A1: Risiko pelaksanaan: Risk Matrix
A2: Kemungkinan dan dampak berskala 1 sampai 5 (penilaian penulis). Nilai = kemungkinan x dampak.
A3: No | B3: Risiko | C3: Penyebab | D3: Kemungkinan | E3: Dampak | F3: Nilai | G3: Tingkat | H3: Tanggapan | I3: Pemilik
A4: 1 | B4: Nasabah besar menolak batas ganti rugi | C4: Kreditur mensyaratkan pertanggungan nilai penuh | D4: 3 | E4: 4 | F4: =D4*E4 -> 12 | G4: =IF(F4>=15,"Tinggi",IF(F4>=8,"Sedang","Rendah")) -> Sedang | H4: Lapisan di atas batas ditempatkan pada penanggung lain lewat koasuransi; mulai dari perpanjangan | I4: Underwriting
A5: 2 | B5: Model meleset dari klaim nyata | C5: Kurva kerentanan dan eksposur per premi tidak pasti | D5: 3 | E5: 5 | F5: =D5*E5 -> 15 | G5: =IF(F5>=15,"Tinggi",IF(F5>=8,"Sedang","Rendah")) -> Tinggi | H5: Target memuat kurva terberat; kalibrasi tahunan; validasi independen; rentang target 160% sampai 195% | I5: Aktuaria
A6: 3 | B6: Premi hilang lebih besar dari perkiraan | C6: Nasabah memindahkan seluruh polis, bukan hanya jaminan gempa | D6: 3 | E6: 3 | F6: =D6*E6 -> 9 | G6: =IF(F6>=15,"Tinggi",IF(F6>=8,"Sedang","Rendah")) -> Sedang | H6: Pantau retensi per pialang; paket harga jaminan kebakaran | I6: Pemasaran
A7: 4 | B7: Data lokasi tidak akurat | C7: Alamat tanpa koordinat; satu polis banyak lokasi | D7: 3 | E7: 3 | F7: =D7*E7 -> 9 | G7: =IF(F7>=15,"Tinggi",IF(F7>=8,"Sedang","Rendah")) -> Sedang | H7: Koordinat wajib untuk risiko besar; audit data per kuartal | I7: Operasi
A8: 5 | B8: Gempa besar sebelum penyangga terbentuk | C8: Penyangga dibentuk dari laba tahun pertama | D8: 1 | E8: 5 | F8: =D8*E8 -> 5 | G8: =IF(F8>=15,"Tinggi",IF(F8>=8,"Sedang","Rendah")) -> Rendah | H8: Batas ganti rugi berlaku lebih dulu; pembagian laba ditunda | I8: Direksi
A9: 6 | B9: Perubahan aturan permodalan | C9: Rancangan aturan modal baru berlaku bertahap mulai 2027 | D9: 2 | E9: 3 | F9: =D9*E9 -> 6 | G9: =IF(F9>=15,"Tinggi",IF(F9>=8,"Sedang","Rendah")) -> Rendah | H9: Mesin simulasi memisahkan parameter regulasi; hitung ulang saat aturan terbit | I9: Kepatuhan
A10: 7 | B10: Guncangan pasar bersamaan dengan bencana | C10: Penjualan aset saat harga turun | D10: 2 | E10: 3 | F10: =D10*E10 -> 6 | G10: =IF(F10>=15,"Tinggi",IF(F10>=8,"Sedang","Rendah")) -> Rendah | H10: Kantong likuiditas dari kas dan deposito; SBN bertenor pendek sampai menengah | I10: Investasi
A12: Jumlah risiko per tingkat
B13: Tinggi | D13: =COUNTIF($G$4:$G$10,B13) -> 1
B14: Sedang | D14: =COUNTIF($G$4:$G$10,B14) -> 3
B15: Rendah | D15: =COUNTIF($G$4:$G$10,B15) -> 3

Sheet Peta_Jalan_KPI
A1: Pelaksanaan: Roadmap dan KPI
A3: Tahap | B3: Waktu | C3: Kegiatan | D3: Keluaran
A4: 1. Dasar | B4: Triwulan IV 2026 | C4: Persetujuan direksi dan dewan komisaris; basis data eksposur; mesin simulasi dipasang | D4: Kebijakan Geo-Solvency Shield; data polis bergeokode
A5: 2. Produk | B5: Triwulan I 2027 | C5: Klausul first loss untuk jaminan gempa di zona inti; pedoman underwriting; pelatihan | D5: Klausul dan tarif siap dipakai
A6: 3. Berlaku bertahap | B6: Triwulan II 2027 | C6: Batas ganti rugi berlaku untuk polis baru dan perpanjangan risiko di atas Rp50 miliar di zona inti | D6: Sekitar 82% eksposur zona inti berbatas pada akhir siklus perpanjangan
A7: 4. Berlaku penuh | B7: Triwulan III sampai IV 2027 | C7: Seluruh risiko zona inti; kantong likuiditas dibentuk; laba ditahan sampai target tercapai | D7: Rasio solvabilitas pada target; kas dan deposito menutup klaim satu kejadian
A8: 5. Kalibrasi | B8: Tiap tahun mulai 2028 | C8: Model dijalankan ulang dengan data polis dan klaim terbaru; validasi independen; target ditinjau | D8: Laporan akumulasi dan uji skenario untuk direksi
A10: Indikator kinerja
A11: Indikator | B11: Sekarang | C11: Sasaran | D11: Sumber ukur
A12: P(R < 100%) setahun, kurva campuran | B12: =Hasil_Model!B16 -> 0.00709 | C12: paling besar 0,50% | D12: Simulasi tahunan
A13: P(R < 100%) setahun, kurva terberat | B13: =Hasil_Model!B17 -> 0.00837 | C13: paling besar 0,50% | D13: Simulasi tahunan
A14: Rasio solvabilitas | B14: =Hasil_Model!B5 -> 1.2 | C14: paling rendah 190% | D14: Laporan bulanan
A15: Rasio setelah skenario megathrust | B15: =Hasil_Model!B20 -> -1.2221204 | C15: paling rendah 100% | D15: Uji skenario per kuartal
A16: Eksposur zona inti yang berbatas | B16: 0 | C16: 100% | D16: Basis data polis
A17: Kas dan deposito terhadap klaim satu kejadian 1 dalam 200 tahun | B17: 0.65337623 | C17: paling rendah 100% | D17: Laporan investasi
A18: Polis gempa dengan koordinat lokasi | B18: belum diukur | C18: paling rendah 95% | D18: Basis data polis
